{
 "cells": [
  {
   "cell_type": "markdown",
   "metadata": {},
   "source": [
    "## What is Exception?\n",
    "\n",
    "### An exception is an event, which occurs during the execution of a program that disrupts the normal flow of the program's instructions. In general, when a Python script encounters a situation that it cannot cope with, it raises an exception. An exception is a Python object that represents an error.\n",
    "### When a Python script raises an exception, it must either handle the exception immediately otherwise it terminates and quits."
   ]
  },
  {
   "cell_type": "markdown",
   "metadata": {},
   "source": [
    "## Handling an exception\n",
    "\n",
    "### If you have some suspicious code that may raise an exception, you can defend your program by placing the suspicious code in a try: block. After the try: block, include an except: statement, followed by a block of code which handles the problem as elegantly as possible.\n",
    "\n",
    "\n",
    "\n",
    "\n",
    "#### Read More : https://docs.python.org/3/library/exceptions.html"
   ]
  },
  {
   "cell_type": "code",
   "execution_count": 6,
   "metadata": {},
   "outputs": [
    {
     "name": "stdout",
     "output_type": "stream",
     "text": [
      "ISE Department\n",
      "Error: can't find file or read data\n",
      "9\n"
     ]
    }
   ],
   "source": [
    "name = \"ISE Department\"\n",
    "print(name)\n",
    "\n",
    "try:\n",
    "       fh = open(\"testfile\", \"r\")\n",
    "       fh.write(\"This is my test file for exception handling!!\")\n",
    "except FileNotFoundError:\n",
    "        print (\"Error: can\\'t find file or read data\")\n",
    "        \n",
    "else:\n",
    "       print (\"Written content in the file successfully\")\n",
    "       fh.close()\n",
    "c = 4+5\n",
    "print(c)"
   ]
  },
  {
   "cell_type": "markdown",
   "metadata": {},
   "source": [
    "### Same code with out Exception handling\n",
    "#### Due to the sequential execution of code the first print() has been executed. But, due to the error in the file opening section the remaining parts did not executed"
   ]
  },
  {
   "cell_type": "code",
   "execution_count": 2,
   "metadata": {},
   "outputs": [
    {
     "name": "stdout",
     "output_type": "stream",
     "text": [
      "ISE Department\n"
     ]
    },
    {
     "ename": "FileNotFoundError",
     "evalue": "[Errno 2] No such file or directory: 'testfile'",
     "output_type": "error",
     "traceback": [
      "\u001b[1;31m---------------------------------------------------------------------------\u001b[0m",
      "\u001b[1;31mFileNotFoundError\u001b[0m                         Traceback (most recent call last)",
      "\u001b[1;32m<ipython-input-2-e5a0bf44e26c>\u001b[0m in \u001b[0;36m<module>\u001b[1;34m()\u001b[0m\n\u001b[0;32m      1\u001b[0m \u001b[0mname\u001b[0m \u001b[1;33m=\u001b[0m \u001b[1;34m\"ISE Department\"\u001b[0m\u001b[1;33m\u001b[0m\u001b[0m\n\u001b[0;32m      2\u001b[0m \u001b[0mprint\u001b[0m\u001b[1;33m(\u001b[0m\u001b[0mname\u001b[0m\u001b[1;33m)\u001b[0m\u001b[1;33m\u001b[0m\u001b[0m\n\u001b[1;32m----> 3\u001b[1;33m \u001b[0mfh\u001b[0m \u001b[1;33m=\u001b[0m \u001b[0mopen\u001b[0m\u001b[1;33m(\u001b[0m\u001b[1;34m\"testfile\"\u001b[0m\u001b[1;33m,\u001b[0m \u001b[1;34m\"r\"\u001b[0m\u001b[1;33m)\u001b[0m\u001b[1;33m\u001b[0m\u001b[0m\n\u001b[0m\u001b[0;32m      4\u001b[0m \u001b[0mfh\u001b[0m\u001b[1;33m.\u001b[0m\u001b[0mwrite\u001b[0m\u001b[1;33m(\u001b[0m\u001b[1;34m\"This is my test file for exception handling!!\"\u001b[0m\u001b[1;33m)\u001b[0m\u001b[1;33m\u001b[0m\u001b[0m\n\u001b[0;32m      5\u001b[0m \u001b[1;33m\u001b[0m\u001b[0m\n",
      "\u001b[1;31mFileNotFoundError\u001b[0m: [Errno 2] No such file or directory: 'testfile'"
     ]
    }
   ],
   "source": [
    "name = \"ISE Department\"\n",
    "print(name)\n",
    "fh = open(\"testfile\", \"r\")\n",
    "fh.write(\"This is my test file for exception handling!!\")\n",
    "\n",
    "print (\"Error: can\\'t find file or read data\")\n",
    "\n",
    "print (\"Written content in the file successfully\")\n",
    "fh.close()\n",
    "c = 4+5\n",
    "print(c)"
   ]
  },
  {
   "cell_type": "markdown",
   "metadata": {},
   "source": [
    "### Exception without error code will also work"
   ]
  },
  {
   "cell_type": "code",
   "execution_count": 7,
   "metadata": {},
   "outputs": [
    {
     "name": "stdout",
     "output_type": "stream",
     "text": [
      "Error: can't find file or read data\n"
     ]
    }
   ],
   "source": [
    "try:\n",
    "       fh = open(\"testfile\", \"r\")\n",
    "       fh.write(\"This is my test file for exception handling!!\")\n",
    "except:\n",
    "       print (\"Error: can\\'t find file or read data\")\n",
    "else:\n",
    "       print (\"Written content in the file successfully\")\n",
    "       fh.close()"
   ]
  },
  {
   "cell_type": "markdown",
   "metadata": {},
   "source": [
    "## The try-finally Clause\n",
    "\n",
    "### You can use a finally: block along with a try: block. The finally block is a place to put any code that must execute, whether the try-block raised an exception or not. The syntax of the try-finally statement is this âˆ’"
   ]
  },
  {
   "cell_type": "code",
   "execution_count": 10,
   "metadata": {},
   "outputs": [
    {
     "name": "stdout",
     "output_type": "stream",
     "text": [
      "File doesn't exists\n",
      "Error: can't find file or read data\n"
     ]
    }
   ],
   "source": [
    "try:\n",
    "   fh = open(\"testfile\", \"r\")\n",
    "   fh.write(\"This is my test file for exception handling!!\")\n",
    "except:\n",
    "    print(\"File doesn't exists\")\n",
    "    \n",
    "finally:\n",
    "   print (\"Error: can\\'t find file or read data\")"
   ]
  },
  {
   "cell_type": "markdown",
   "metadata": {},
   "source": [
    "## Argument of an Exception\n",
    "\n",
    "### An exception can have an argument, which is a value that gives additional information about the problem. The contents of the argument vary by exception. You capture an exception's argument by supplying a variable in the except clause as follows"
   ]
  },
  {
   "cell_type": "code",
   "execution_count": 1,
   "metadata": {},
   "outputs": [
    {
     "name": "stdout",
     "output_type": "stream",
     "text": [
      "The argument does not contain numbers\n",
      " invalid literal for int() with base 10: 'xyz'\n"
     ]
    }
   ],
   "source": [
    "def temp_convert(var):\n",
    "   try:\n",
    "      return int(var)\n",
    "   except ValueError as Argument:\n",
    "      print (\"The argument does not contain numbers\\n\", Argument)\n",
    "\n",
    "# Call above function here.\n",
    "temp_convert(\"xyz\");"
   ]
  },
  {
   "cell_type": "markdown",
   "metadata": {},
   "source": [
    "## User Defined Exceptions\n",
    "\n",
    "### You can raise exceptions in several ways by using the raise statement. The general syntax for the raise statement is as follows"
   ]
  },
  {
   "cell_type": "code",
   "execution_count": 21,
   "metadata": {},
   "outputs": [
    {
     "name": "stdout",
     "output_type": "stream",
     "text": [
      "('An error occurred',)\n"
     ]
    }
   ],
   "source": [
    "try:\n",
    "   raise Exception('An error occurred')\n",
    "except Exception as e:\n",
    "   print (e.args)"
   ]
  },
  {
   "cell_type": "code",
   "execution_count": null,
   "metadata": {
    "collapsed": true
   },
   "outputs": [],
   "source": []
  }
 ],
 "metadata": {
  "kernelspec": {
   "display_name": "Python 3",
   "language": "python",
   "name": "python3"
  },
  "language_info": {
   "codemirror_mode": {
    "name": "ipython",
    "version": 3
   },
   "file_extension": ".py",
   "mimetype": "text/x-python",
   "name": "python",
   "nbconvert_exporter": "python",
   "pygments_lexer": "ipython3",
   "version": "3.6.5"
  }
 },
 "nbformat": 4,
 "nbformat_minor": 2
}
